<?xml version="1.0" encoding="UTF-8" ?>
<robot name="mybot" xmlns:xacro="http://www.ros.org/wiki/xacro">
    <xacro:property name="cameraSize" value="0.05"/>
    <xacro:property name="cameraMass" value="0.1"/>

    <!--base_footprint-->
    <link name="base_footprint">
        <inertial>
            <mass value="0.0001"/>
            <origin xyz="0 0 0"/>
            <inertia ixx="0.0001" ixy="0.0" ixz="0.0"
                     iyy="0.0001" iyz="0.0"
                     izz="0.0001"/>
        </inertial>
        <visual>
            <geometry>
                <box size="0.001 0.001 0.001"/>
            </geometry>
            <origin rpy="0 0 0" xyz="0 0 0"/>
        </visual>
    </link>

    <!--base_link-->
    <link name='base_link'>
        <pose>0 0 0 0 0 0</pose>

        <inertial>
            <mass value="5.0"/>
            <origin xyz="0.0 0 0" rpy=" 0 0 0"/>
            <inertia
                    ixx="0.1" ixy="0" ixz="0"
                    iyy="0.1" iyz="0"
                    izz="0.1"
            />
        </inertial>

        <collision name='collision'>
            <geometry>
                <mesh filename="package://mybot_description/meshes/base_link.STL"/>
            </geometry>
        </collision>

        <visual name='base_link_visual'>
            <origin xyz="0 0 0" rpy=" 0 0 0"/>
            <geometry>
                <mesh filename="package://mybot_description/meshes/base_link.STL"/>
            </geometry>
        </visual>
    </link>

    <!--left wheel-->
    <link name="left_wheel">
        <collision name="collision">
            <origin xyz="0 0 0" rpy="0 1.5707 1.5707"/>
            <geometry>
                <mesh filename="package://mybot_description/meshes/wheel.STL"/>
            </geometry>
        </collision>
        <visual name="left_wheel_visual">
            <origin xyz="0 0 0" rpy="0 1.5707 1.5707"/>
            <geometry>
                <mesh filename="package://mybot_description/meshes/wheel.STL"/>
            </geometry>
        </visual>
        <inertial>
            <origin xyz="0 0 0" rpy="0 1.5707 1.5707"/>
            <mass value="0.5"/>
            <inertia
                    ixx=".1" ixy="0.0" ixz="0.0"
                    iyy=".1" iyz="0.0"
                    izz=".1"/>
        </inertial>
    </link>

    <!--rifht wheel-->
    <link name="right_wheel">
        <collision name="collision">
            <origin xyz="0 0 0" rpy="0 1.5707 1.5707"/>
            <geometry>
                <mesh filename="package://mybot_description/meshes/wheel.STL"/>
            </geometry>
        </collision>
        <visual name="right_wheel_visual">
            <origin xyz="0 0 0" rpy="0 1.5707 1.5707"/>
            <geometry>
                <mesh filename="package://mybot_description/meshes/wheel.STL"/>
            </geometry>
        </visual>
        <inertial>
            <origin xyz="0 0 0" rpy="0 1.5707 1.5707"/>
            <mass value="0.5"/>
            <inertia
                    ixx=".1" ixy="0.0" ixz="0.0"
                    iyy=".1" iyz="0.0"
                    izz=".1"/>
        </inertial>
    </link>

    <!--joints-->
    <joint name="base_footprint_joint" type="fixed">
        <origin xyz="0 0 0"/>
        <parent link="base_footprint"/>
        <child link="base_link"/>
    </joint>

    <joint type="continuous" name="left_wheel_joint">
        <origin xyz="-0.12402 0.15902 -0.06636" rpy="0 0 0"/>
        <child link="left_wheel"/>
        <parent link="base_link"/>
        <axis xyz="0 1 0" rpy="0 0 0"/>
        <limit effort="10000" velocity="1000"/>
        <joint_properties damping="1.0" friction="1.0"/>
    </joint>

    <joint type="continuous" name="right_wheel_joint">
        <origin xyz="-0.12402 -0.15902 -0.06636" rpy="0 0 0"/>
        <child link="right_wheel"/>
        <parent link="base_link"/>
        <axis xyz="0 1 0" rpy="0 0 0"/>
        <limit effort="10000" velocity="1000"/>
        <joint_properties damping="1.0" friction="1.0"/>
    </joint>
</robot>